2019-01-15T14:29:48|CRITICAL|root|Unhandled exception:Traceback (most recent call last):
  File "C:\ProgramData\Anaconda3\lib\site-packages\ScopeFoundry\hardware.py", line 160, in <lambda>
    op_button.clicked.connect(lambda checked, f=op_func: f())
  File "C:\LabPrograms\Python\nidaqmx_test\ni_hardware.py", line 65, in start
    self.AO_device.start_task()
  File "C:\LabPrograms\Python\nidaqmx_test\ni_device.py", line 51, in start_task
    self.task.start()
  File "C:\ProgramData\Anaconda3\lib\site-packages\nidaqmx\task.py", line 1026, in start
    check_for_error(error_code)
  File "C:\ProgramData\Anaconda3\lib\site-packages\nidaqmx\errors.py", line 127, in check_for_error
    raise DaqError(error_buffer.value.decode("utf-8"), error_code)
nidaqmx.errors.DaqError: Specified operation cannot be performed while the task is running.
Task Name: _unnamedTask<2>

Status Code: -200479

