2019-01-21T11:07:31|CRITICAL|root|Unhandled exception:Traceback (most recent call last):
  File "C:\ProgramData\Anaconda3\lib\site-packages\ScopeFoundry\hardware.py", line 208, in enable_connection
    raise err
  File "C:\ProgramData\Anaconda3\lib\site-packages\ScopeFoundry\hardware.py", line 204, in enable_connection
    self.connect()
  File "C:\LabPrograms\Python\nidaqmx_test\ni_do_hardware.py", line 32, in connect
    self.DO_device = NI_DO_device(channel=self.channel.val, debug=self.debug_mode.val)
TypeError: __init__() got an unexpected keyword argument 'debug'

