2019-01-21T18:30:56|CRITICAL|root|Unhandled exception:Traceback (most recent call last):
  File "C:\ProgramData\Anaconda3\lib\site-packages\ScopeFoundry\hardware.py", line 208, in enable_connection
    raise err
  File "C:\ProgramData\Anaconda3\lib\site-packages\ScopeFoundry\hardware.py", line 204, in enable_connection
    self.connect()
  File "C:\LabPrograms\Python\nidaqmx_test\ni_co_hardware.py", line 42, in connect
    trigger_source=self.trigger_source.val, trigger_edge=self.trigger_edge.val, debug=self.debug_mode.val)
  File "C:\LabPrograms\Python\nidaqmx_test\ni_co_device.py", line 23, in __init__
    self.Task()
  File "C:\LabPrograms\Python\nidaqmx_test\ni_co_device.py", line 31, in Task
    self.task.co_channels.add_co_pulse_chan_time(counter=self.channel, units=TimeUnits.SECONDS, idle_state=nidaqmx.constants.Level.LOW, initial_delay=0, low_time=0.01, high_time=0.01)
NameError: name 'TimeUnits' is not defined

