2019-02-05T10:29:34|CRITICAL|root|Unhandled exception:Traceback (most recent call last):
  File "C:\ProgramData\Anaconda3\lib\site-packages\ScopeFoundry\hardware.py", line 160, in <lambda>
    op_button.clicked.connect(lambda checked, f=op_func: f())
  File "C:\LabPrograms\Python\nidaqmx_test\ni_co_hardware.py", line 61, in start
    self.CO_device.start_task()
  File "C:\LabPrograms\Python\nidaqmx_test\ni_co_device.py", line 40, in start_task
    self.task.start()
  File "C:\ProgramData\Anaconda3\lib\site-packages\nidaqmx\task.py", line 1026, in start
    check_for_error(error_code)
  File "C:\ProgramData\Anaconda3\lib\site-packages\nidaqmx\errors.py", line 127, in check_for_error
    raise DaqError(error_buffer.value.decode("utf-8"), error_code)
nidaqmx.errors.DaqError: Specified route cannot be satisfied, because the hardware does not support it.
Property: DAQmx_DigEdge_StartTrig_Src
Property: DAQmx_DigEdge_StartTrig_Edge
Source Device: Dev2
Source Terminal: Ctr0Source

Task Name: _unnamedTask<1>

Status Code: -89136

