2019-01-14T11:09:39|CRITICAL|root|Unhandled exception:Traceback (most recent call last):
  File "C:\ProgramData\Anaconda3\lib\site-packages\ScopeFoundry\hardware.py", line 208, in enable_connection
    raise err
  File "C:\ProgramData\Anaconda3\lib\site-packages\ScopeFoundry\hardware.py", line 204, in enable_connection
    self.connect()
  File "C:\LabPrograms\Python\nidaqmx_test\ni_hardware.py", line 28, in connect
    frequency=self.frequency.val, offset=self.offset.val, debug=self.debug_mode.val)
  File "C:\LabPrograms\Python\nidaqmx_test\ni_device.py", line 19, in __init__
    self.startTask()
  File "C:\LabPrograms\Python\nidaqmx_test\ni_device.py", line 27, in startTask
    self.task.ao_channels.add_ao_voltage_chan(physical_channel=self.channel.val, min_val=0.0, max_val=5.0) #add an analog output channel
AttributeError: 'str' object has no attribute 'val'

