2019-01-14T11:13:02|CRITICAL|root|Unhandled exception:Traceback (most recent call last):
  File "C:\ProgramData\Anaconda3\lib\site-packages\ScopeFoundry\hardware.py", line 208, in enable_connection
    raise err
  File "C:\ProgramData\Anaconda3\lib\site-packages\ScopeFoundry\hardware.py", line 204, in enable_connection
    self.connect()
  File "C:\LabPrograms\Python\nidaqmx_test\ni_hardware.py", line 28, in connect
    frequency=self.frequency.val, offset=self.offset.val, debug=self.debug_mode.val)
  File "C:\LabPrograms\Python\nidaqmx_test\ni_device.py", line 19, in __init__
    self.startTask()
  File "C:\LabPrograms\Python\nidaqmx_test\ni_device.py", line 31, in startTask
    self.task.ao_channels.add_ao_func_gen_chan(physical_channel=self.channel, type=dict.get(self.mode), freq=self.frequency, amplitude=self.amplitude, offset=self.offset)
  File "C:\ProgramData\Anaconda3\lib\site-packages\nidaqmx\_task_modules\ao_channel_collection.py", line 141, in add_ao_func_gen_chan
    type.value, freq, amplitude, offset)
AttributeError: 'NoneType' object has no attribute 'value'

