2019-01-21T10:04:46|CRITICAL|root|Unhandled exception:Traceback (most recent call last):
  File "C:\LabPrograms\Python\nidaqmx_test\ni_app.py", line 35, in <module>
    app = NI_App(sys.argv)
  File "C:\ProgramData\Anaconda3\lib\site-packages\ScopeFoundry\base_app.py", line 332, in __init__
    self.setup()
  File "C:\LabPrograms\Python\nidaqmx_test\ni_app.py", line 19, in setup
    self.add_hardware(NI_AO_hw(self))
  File "C:\ProgramData\Anaconda3\lib\site-packages\ScopeFoundry\hardware.py", line 80, in __init__
    self.setup()
  File "C:\LabPrograms\Python\nidaqmx_test\ni_ao_hardware.py", line 13, in setup
    system = nidaqmx.system.System.local()
NameError: name 'nidaqmx' is not defined

