2019-01-14T12:08:57|CRITICAL|root|Unhandled exception:Traceback (most recent call last):
  File "C:\ProgramData\Anaconda3\lib\site-packages\ScopeFoundry\hardware.py", line 208, in enable_connection
    raise err
  File "C:\ProgramData\Anaconda3\lib\site-packages\ScopeFoundry\hardware.py", line 204, in enable_connection
    self.connect()
  File "C:\LabPrograms\Python\nidaqmx_test\ni_hardware.py", line 28, in connect
    frequency=self.frequency.val, offset=self.offset.val, debug=self.debug_mode.val)
  File "C:\LabPrograms\Python\nidaqmx_test\ni_device.py", line 19, in __init__
    self.startTask()
  File "C:\LabPrograms\Python\nidaqmx_test\ni_device.py", line 27, in startTask
    self.task.ao_channels.add_ao_voltage_chan(physical_channel=self.channel, min_val=0.0, max_val=5.0) #add an analog output channel
  File "C:\ProgramData\Anaconda3\lib\site-packages\nidaqmx\_task_modules\ao_channel_collection.py", line 191, in add_ao_voltage_chan
    check_for_error(error_code)
  File "C:\ProgramData\Anaconda3\lib\site-packages\nidaqmx\errors.py", line 127, in check_for_error
    raise DaqError(error_buffer.value.decode("utf-8"), error_code)
nidaqmx.errors.DaqError: Device cannot be accessed.  Possible causes:

Device is no longer present in the system.
Device is not powered.
Device is powered, but was temporarily without power.
Device and/or chassis driver support may have been removed.
Device is damaged.

Ensure the device is properly connected and turned on. Ensure the device and/or chassis is supported in the current version of the driver. Check the device's status in NI MAX. Turn the computer off and on again. If you suspect that the device is damaged, contact National Instruments at ni.com/support.
Device Specified: Dev1

Task Name: _unnamedTask<0>

Status Code: -201003

