2019-01-21T11:08:40|CRITICAL|root|Unhandled exception:Traceback (most recent call last):
  File "C:\ProgramData\Anaconda3\lib\site-packages\ScopeFoundry\hardware.py", line 208, in enable_connection
    raise err
  File "C:\ProgramData\Anaconda3\lib\site-packages\ScopeFoundry\hardware.py", line 204, in enable_connection
    self.connect()
  File "C:\LabPrograms\Python\nidaqmx_test\ni_do_hardware.py", line 32, in connect
    self.DO_device = NI_DO_device(channel=self.channel.val, debug=self.debug_mode.val)
  File "C:\LabPrograms\Python\nidaqmx_test\ni_do_device.py", line 13, in __init__
    self.dummy = dummy
NameError: name 'dummy' is not defined

