2019-02-04T17:05:44|CRITICAL|root|Unhandled exception:Traceback (most recent call last):
  File "C:\LabPrograms\Python\nidaqmx_test\ni_app.py", line 39, in <module>
    app = NI_App(sys.argv)
  File "C:\ProgramData\Anaconda3\lib\site-packages\ScopeFoundry\base_app.py", line 332, in __init__
    self.setup()
  File "C:\LabPrograms\Python\nidaqmx_test\ni_app.py", line 22, in setup
    self.add_hardware(NI_DO_hw(self))
  File "C:\ProgramData\Anaconda3\lib\site-packages\ScopeFoundry\hardware.py", line 80, in __init__
    self.setup()
  File "C:\LabPrograms\Python\nidaqmx_test\ni_do_hardware.py", line 19, in setup
    self.channel = self.add_logged_quantity('channel', dtype=str, choices=terminals, initial='Dev2/PFI10')
  File "C:\ProgramData\Anaconda3\lib\site-packages\ScopeFoundry\hardware.py", line 28, in add_logged_quantity
    return self.settings.New(name, **kwargs)
  File "C:\ProgramData\Anaconda3\lib\site-packages\ScopeFoundry\logged_quantity.py", line 1106, in New
    lq = LoggedQuantity(name=name, dtype=dtype, **kwargs)
  File "C:\ProgramData\Anaconda3\lib\site-packages\ScopeFoundry\logged_quantity.py", line 90, in __init__
    self.choices = self._expand_choices(choices)
  File "C:\ProgramData\Anaconda3\lib\site-packages\ScopeFoundry\logged_quantity.py", line 141, in _expand_choices
    for c in choices:
TypeError: 'PhysicalChannel' object is not iterable

