2019-02-05T15:31:25|CRITICAL|root|Unhandled exception:Traceback (most recent call last):
  File "C:\ProgramData\Anaconda3\lib\site-packages\ScopeFoundry\hardware.py", line 160, in <lambda>
    op_button.clicked.connect(lambda checked, f=op_func: f())
  File "C:\LabPrograms\Python\nidaqmx_test\ni_co_hardware.py", line 61, in start
    self.CO_device.start_task()
  File "C:\LabPrograms\Python\nidaqmx_test\ni_co_device.py", line 40, in start_task
    self.task.start()
  File "C:\ProgramData\Anaconda3\lib\site-packages\nidaqmx\task.py", line 1026, in start
    check_for_error(error_code)
  File "C:\ProgramData\Anaconda3\lib\site-packages\nidaqmx\errors.py", line 127, in check_for_error
    raise DaqError(error_buffer.value.decode("utf-8"), error_code)
nidaqmx.errors.DaqError: Source terminal to be routed could not be found on the device.

Make sure the terminal name is valid for the specified device. Refer to Measurement & Automation Explorer for valid terminal names.
Property: DAQmx_DigEdge_StartTrig_Src
Property: DAQmx_DigEdge_StartTrig_Edge
Source Device: Dev2
Source Terminal: Dev2/ctr1
Channel Name: Dev2/ctr0

Task Name: _unnamedTask<0>

Status Code: -89120

