2019-01-14T11:11:38|CRITICAL|root|Unhandled exception:Traceback (most recent call last):
  File "C:\ProgramData\Anaconda3\lib\site-packages\ScopeFoundry\logged_quantity.py", line 311, in update_choice_index_value
    self.update_value(self.choices[new_choice_index][1], **kwargs)
  File "C:\ProgramData\Anaconda3\lib\site-packages\ScopeFoundry\logged_quantity.py", line 241, in update_value
    self.hardware_set_func(self.val)
  File "C:\LabPrograms\Python\nidaqmx_test\ni_device.py", line 52, in set_mode
    self.startTask()
  File "C:\LabPrograms\Python\nidaqmx_test\ni_device.py", line 31, in startTask
    self.task.ao_channels.add_ao_func_gen_chan(physical_channel=self.channel, type=dict.get(self.mode), freq=self.frequency.val, amplitude=self.amplitude.val, offset=self.offset.val)
AttributeError: 'float' object has no attribute 'val'

