2019-01-15T11:20:03|CRITICAL|root|Unhandled exception:Traceback (most recent call last):
  File "C:\ProgramData\Anaconda3\lib\site-packages\ScopeFoundry\hardware.py", line 208, in enable_connection
    raise err
  File "C:\ProgramData\Anaconda3\lib\site-packages\ScopeFoundry\hardware.py", line 204, in enable_connection
    self.connect()
  File "C:\LabPrograms\Python\nidaqmx_test\ni_hardware.py", line 36, in connect
    frequency=self.frequency.val, offset=self.offset.val, debug=self.debug_mode.val)
  File "C:\LabPrograms\Python\nidaqmx_test\ni_device.py", line 30, in __init__
    self.startTask()
AttributeError: 'NI_DAQ_device' object has no attribute 'startTask'

