2019-01-14T11:10:23|CRITICAL|root|Unhandled exception:Traceback (most recent call last):
  File "C:\ProgramData\Anaconda3\lib\site-packages\ScopeFoundry\logged_quantity.py", line 241, in update_value
    self.hardware_set_func(self.val)
  File "C:\LabPrograms\Python\nidaqmx_test\ni_device.py", line 57, in set_ampl
    if self.mode.val == "ao_voltage":
AttributeError: 'str' object has no attribute 'val'

