2019-01-15T11:22:45|CRITICAL|root|Unhandled exception:Traceback (most recent call last):
  File "C:\ProgramData\Anaconda3\lib\site-packages\ScopeFoundry\hardware.py", line 160, in <lambda>
    op_button.clicked.connect(lambda checked, f=op_func: f())
  File "C:\LabPrograms\Python\nidaqmx_test\ni_hardware.py", line 64, in start
    self.AO_device.start_task()
AttributeError: 'NI_DAQ_device' object has no attribute 'start_task'

