2019-01-21T11:10:03|CRITICAL|root|Unhandled exception:Traceback (most recent call last):
  File "C:\ProgramData\Anaconda3\lib\site-packages\ScopeFoundry\hardware.py", line 208, in enable_connection
    raise err
  File "C:\ProgramData\Anaconda3\lib\site-packages\ScopeFoundry\hardware.py", line 204, in enable_connection
    self.connect()
  File "C:\LabPrograms\Python\nidaqmx_test\ni_do_hardware.py", line 32, in connect
    self.DO_device = NI_DO_device(channel=self.channel.val, debug=self.debug_mode.val)
  File "C:\LabPrograms\Python\nidaqmx_test\ni_do_device.py", line 16, in __init__
    self.Task()
  File "C:\LabPrograms\Python\nidaqmx_test\ni_do_device.py", line 23, in Task
    self.task.do_channels.add_do_chan(lines=channel)
NameError: name 'channel' is not defined

