2019-01-21T11:17:10|CRITICAL|root|Unhandled exception:Traceback (most recent call last):
  File "C:\ProgramData\Anaconda3\lib\site-packages\ScopeFoundry\hardware.py", line 208, in enable_connection
    raise err
  File "C:\ProgramData\Anaconda3\lib\site-packages\ScopeFoundry\hardware.py", line 204, in enable_connection
    self.connect()
  File "C:\LabPrograms\Python\nidaqmx_test\ni_ao_hardware.py", line 43, in connect
    self.AO_device = NI_DAQ_device(channel=self.channel.val, mode=self.mode.val, sample_mode=self.sample_mode.val,
NameError: name 'NI_DAQ_device' is not defined

