2019-02-05T15:59:27|CRITICAL|root|Unhandled exception:Traceback (most recent call last):
  File "C:\ProgramData\Anaconda3\lib\site-packages\ScopeFoundry\hardware.py", line 208, in enable_connection
    raise err
  File "C:\ProgramData\Anaconda3\lib\site-packages\ScopeFoundry\hardware.py", line 204, in enable_connection
    self.connect()
  File "C:\LabPrograms\Python\nidaqmx_test\ni_co_hardware.py", line 37, in connect
    trigger_source=self.trigger_source.val, trigger_edge=self.trigger_edge.val, debug=self.debug_mode.val)
  File "C:\LabPrograms\Python\nidaqmx_test\ni_co_device.py", line 24, in __init__
    self.Task()
  File "C:\LabPrograms\Python\nidaqmx_test\ni_co_device.py", line 31, in Task
    self.task.co_channels.add_co_pulse_chan_freq(counter=self.channel, initial_delay=self.initial_delay, freq=self.freq, duty_cycle=self.duty_cycle)
  File "C:\ProgramData\Anaconda3\lib\site-packages\nidaqmx\_task_modules\co_channel_collection.py", line 100, in add_co_pulse_chan_freq
    idle_state.value, initial_delay, freq, duty_cycle)
ctypes.ArgumentError: argument 6: <class 'TypeError'>: wrong type

