2019-01-15T12:05:31|CRITICAL|root|Unhandled exception:Traceback (most recent call last):
  File "C:\ProgramData\Anaconda3\lib\site-packages\ScopeFoundry\logged_quantity.py", line 311, in update_choice_index_value
    self.update_value(self.choices[new_choice_index][1], **kwargs)
  File "C:\ProgramData\Anaconda3\lib\site-packages\ScopeFoundry\logged_quantity.py", line 241, in update_value
    self.hardware_set_func(self.val)
  File "C:\LabPrograms\Python\nidaqmx_test\ni_device.py", line 71, in set_mode
    self.Task()
  File "C:\LabPrograms\Python\nidaqmx_test\ni_device.py", line 42, in Task
    self.task.timing.cfg_samp_clk_timing(rate= self.rate, sample_mode=self.dict.get(self.sample_mode), samps_per_chan=num_samples)
  File "C:\ProgramData\Anaconda3\lib\site-packages\nidaqmx\_task_modules\timing.py", line 3006, in cfg_samp_clk_timing
    samps_per_chan)
ctypes.ArgumentError: argument 6: <class 'TypeError'>: wrong type

