2019-01-15T11:34:31|CRITICAL|root|Unhandled exception:Traceback (most recent call last):
  File "C:\ProgramData\Anaconda3\lib\site-packages\ScopeFoundry\hardware.py", line 160, in <lambda>
    op_button.clicked.connect(lambda checked, f=op_func: f())
  File "C:\LabPrograms\Python\nidaqmx_test\ni_hardware.py", line 65, in start
    self.AO_device.start_task()
  File "C:\LabPrograms\Python\nidaqmx_test\ni_device.py", line 47, in start_task
    self.task.start()
  File "C:\ProgramData\Anaconda3\lib\site-packages\nidaqmx\task.py", line 1026, in start
    check_for_error(error_code)
  File "C:\ProgramData\Anaconda3\lib\site-packages\nidaqmx\errors.py", line 127, in check_for_error
    raise DaqError(error_buffer.value.decode("utf-8"), error_code)
nidaqmx.errors.DaqError: Specified operation cannot be performed while the task is running.
Task Name: _unnamedTask<6>

Status Code: -200479

2019-01-15T11:34:48|CRITICAL|root|Unhandled exception:Traceback (most recent call last):
  File "C:\ProgramData\Anaconda3\lib\site-packages\ScopeFoundry\hardware.py", line 160, in <lambda>
    op_button.clicked.connect(lambda checked, f=op_func: f())
  File "C:\LabPrograms\Python\nidaqmx_test\ni_hardware.py", line 65, in start
    self.AO_device.start_task()
  File "C:\LabPrograms\Python\nidaqmx_test\ni_device.py", line 47, in start_task
    self.task.start()
  File "C:\ProgramData\Anaconda3\lib\site-packages\nidaqmx\task.py", line 1026, in start
    check_for_error(error_code)
  File "C:\ProgramData\Anaconda3\lib\site-packages\nidaqmx\errors.py", line 127, in check_for_error
    raise DaqError(error_buffer.value.decode("utf-8"), error_code)
nidaqmx.errors.DaqError: Specified operation cannot be performed while the task is running.
Task Name: _unnamedTask<6>

Status Code: -200479

2019-01-15T11:34:48|CRITICAL|root|Unhandled exception:Traceback (most recent call last):
  File "C:\ProgramData\Anaconda3\lib\site-packages\ScopeFoundry\hardware.py", line 160, in <lambda>
    op_button.clicked.connect(lambda checked, f=op_func: f())
  File "C:\LabPrograms\Python\nidaqmx_test\ni_hardware.py", line 65, in start
    self.AO_device.start_task()
  File "C:\LabPrograms\Python\nidaqmx_test\ni_device.py", line 47, in start_task
    self.task.start()
  File "C:\ProgramData\Anaconda3\lib\site-packages\nidaqmx\task.py", line 1026, in start
    check_for_error(error_code)
  File "C:\ProgramData\Anaconda3\lib\site-packages\nidaqmx\errors.py", line 127, in check_for_error
    raise DaqError(error_buffer.value.decode("utf-8"), error_code)
nidaqmx.errors.DaqError: Specified operation cannot be performed while the task is running.
Task Name: _unnamedTask<6>

Status Code: -200479

2019-01-15T11:34:48|CRITICAL|root|Unhandled exception:Traceback (most recent call last):
  File "C:\ProgramData\Anaconda3\lib\site-packages\ScopeFoundry\hardware.py", line 160, in <lambda>
    op_button.clicked.connect(lambda checked, f=op_func: f())
  File "C:\LabPrograms\Python\nidaqmx_test\ni_hardware.py", line 65, in start
    self.AO_device.start_task()
  File "C:\LabPrograms\Python\nidaqmx_test\ni_device.py", line 47, in start_task
    self.task.start()
  File "C:\ProgramData\Anaconda3\lib\site-packages\nidaqmx\task.py", line 1026, in start
    check_for_error(error_code)
  File "C:\ProgramData\Anaconda3\lib\site-packages\nidaqmx\errors.py", line 127, in check_for_error
    raise DaqError(error_buffer.value.decode("utf-8"), error_code)
nidaqmx.errors.DaqError: Specified operation cannot be performed while the task is running.
Task Name: _unnamedTask<6>

Status Code: -200479

2019-01-15T11:34:48|CRITICAL|root|Unhandled exception:Traceback (most recent call last):
  File "C:\ProgramData\Anaconda3\lib\site-packages\ScopeFoundry\hardware.py", line 160, in <lambda>
    op_button.clicked.connect(lambda checked, f=op_func: f())
  File "C:\LabPrograms\Python\nidaqmx_test\ni_hardware.py", line 65, in start
    self.AO_device.start_task()
  File "C:\LabPrograms\Python\nidaqmx_test\ni_device.py", line 47, in start_task
    self.task.start()
  File "C:\ProgramData\Anaconda3\lib\site-packages\nidaqmx\task.py", line 1026, in start
    check_for_error(error_code)
  File "C:\ProgramData\Anaconda3\lib\site-packages\nidaqmx\errors.py", line 127, in check_for_error
    raise DaqError(error_buffer.value.decode("utf-8"), error_code)
nidaqmx.errors.DaqError: Specified operation cannot be performed while the task is running.
Task Name: _unnamedTask<6>

Status Code: -200479

2019-01-15T11:36:12|CRITICAL|root|Unhandled exception:Traceback (most recent call last):
  File "C:\ProgramData\Anaconda3\lib\site-packages\ScopeFoundry\logged_quantity.py", line 241, in update_value
    self.hardware_set_func(self.val)
  File "C:\LabPrograms\Python\nidaqmx_test\ni_device.py", line 118, in set_num_samples
    self.task.timing.cfg_samp_clk_timing(samps_per_chan = num_samples )
TypeError: cfg_samp_clk_timing() missing 1 required positional argument: 'rate'

